model
name = test
revision = 8411
size = 20 40 20
origin = -y
shell = Outline 0.25
material type = toon, lighting = smooth, deform = 1 1
  colors = B:#620042
material type = basic, lighting = smooth, roughness = 0, refractionRatio = 1, side = back
  colors = Outline:#000
voxels
17(380-420B)380-246B-19B2-152B380-267B-19B-132B380-163B-123B-5B-126B
